Workbook
Name pba_billed_month: 'PBA-DATA'!$B$35
Name pba_cash_closing: 'PBA-DATA'!$B$14
Name pba_cash_opening: 'PBA-DATA'!$B$13
Name pba_cash_restricted: 'PBA-DATA'!$B$15
Name pba_clients_active: 'PBA-DATA'!$B$24
Name pba_clients_added: 'PBA-DATA'!$B$25
Name pba_clients_lost: 'PBA-DATA'!$B$26
Name pba_collections_month: 'PBA-DATA'!$B$36
Name pba_expenses_accrual: 'PBA-DATA'!$B$18
Name pba_gross_burn: 'PBA-DATA'!$B$16
Name pba_net_burn: 'PBA-DATA'!$B$17
Name pba_partner_share_paid: 'PBA-DATA'!$B$23
Name pba_payables_total: 'PBA-DATA'!$B$34
Name pba_receivables_0_30: 'PBA-DATA'!$B$30
Name pba_receivables_31_60: 'PBA-DATA'!$B$31
Name pba_receivables_61_90: 'PBA-DATA'!$B$32
Name pba_receivables_90_plus: 'PBA-DATA'!$B$33
Name pba_receivables_total: 'PBA-DATA'!$B$29
Name pba_revenue_project: 'PBA-DATA'!$B$22
Name pba_revenue_service: 'PBA-DATA'!$B$21
Name pba_revenue_subscription: 'PBA-DATA'!$B$20
Name pba_revenue_total: 'PBA-DATA'!$B$19
Name pba_top5_client_revenue: 'PBA-DATA'!$B$28
Name pba_top_client_revenue: 'PBA-DATA'!$B$27
Name pba_gst_output: 'PBA-DATA'!$B$39
Name pba_gst_itc: 'PBA-DATA'!$B$40
Name pba_gst_paid_cash: 'PBA-DATA'!$B$41
Name pba_igst: 'PBA-DATA'!$B$42
Name pba_cgst: 'PBA-DATA'!$B$43
Name pba_sgst: 'PBA-DATA'!$B$44
Name pba_tds_salary: 'PBA-DATA'!$B$45
Name pba_tds_vendor: 'PBA-DATA'!$B$46
Name pba_tds_rent: 'PBA-DATA'!$B$47
Name pba_pt_paid: 'PBA-DATA'!$B$48
Name pba_interest_fees: 'PBA-DATA'!$B$49
Name pba_employees: 'PBA-DATA'!$B$50
Name pba_contractors: 'PBA-DATA'!$B$51
Name pba_notices_open: 'PBA-DATA'!$B$52
Name pba_exp_salaries: 'PBA-DATA'!$B$53
Name pba_exp_contractors: 'PBA-DATA'!$B$54
Name pba_exp_cloud: 'PBA-DATA'!$B$55
Name pba_exp_marketing: 'PBA-DATA'!$B$56
Name pba_exp_rent: 'PBA-DATA'!$B$57
Name pba_exp_travel: 'PBA-DATA'!$B$58
Name pba_exp_software: 'PBA-DATA'!$B$59
Name pba_exp_other: 'PBA-DATA'!$B$60
Name pba_interest_note: 'PBA-DATA'!$B$61

Sheet READ ME
A1: Xploro — Monthly MIS
A2: Prime Bottomline Advisory · template version 1.0
A4: WHAT THIS FILE IS
B5: The agreed monthly management information format for Xploro Private Limited.
B6: One file per month, uploaded to the PBA advisory portal by day 7.
B7: The format is frozen. Please do not insert, delete or rename sheets, rows or columns.
A9: WHY THE FORMAT MATTERS
B10: The portal reads twenty-four figures straight out of this workbook and shows them
B11: to the founder. It finds them on the PBA-DATA sheet, which fills itself from the
B12: sheets you complete. Nobody retypes anything.
B13: If the structure changes, those cells break and the month cannot be published.
A15: HOW TO USE IT
B16: 1. Fill every yellow cell. Yellow means 'type here'.
B17: 2. Leave every white cell alone. Those are calculated.
B18: 3. Open the CHECKS sheet. All five must read PASS.
B19: 4. Save as: Xploro-MIS-YYYY-MM.xlsx (e.g. Xploro-MIS-2026-09.xlsx)
B20: 5. Upload to the portal against that month.
A22: COLOUR LEGEND
B23: Yellow fill, blue text — you type this
B24: White, black text — calculated on this sheet, do not edit
B25: White, green text — pulled from another sheet, do not edit
A27: THIS MONTH
A28: Company | B28: Xploro Private Limited
A29: Month (YYYY-MM) | B29: 2026-09
A30: Prepared by | B30: SPARC & Co, Chartered Accountants
A31: Prepared on | B31: 07/10/2026
A33: NOTE | B33: The September 2026 figures in this file are an illustrative example.
B34: Overwrite every yellow cell with the real month's numbers.
A36: Questions | B36: Swetha, Prime Bottomline Advisory

Sheet Profit and Loss
A1: Profit and Loss
A2: All figures exclude GST. Revenue is stated net of partner shares.
A4: Line | B4: This month | C4: Last month
A6: REVENUE (net of revenue-share partners)
A7: Subscription | B7: 210000 | C7: 175000
A8: Service | B8: 340000 | C8: 320000
A9: Project | B9: 160000 | C9: 163000
A10: Net revenue | B10: =SUM(B7:B9) -> 710000 | C10: =SUM(C7:C9) -> 658000
A12: Paid or accrued to revenue-share partners | B12: 180000 | C12: 165000
A13: Memo: gross revenue before partner share | B13: =B10+B12 -> 890000 | C13: =C10+C12 -> 823000
A15: EXPENSES (accrual basis, excluding GST)
A16: Personnel | B16: 480000 | C16: 455000
A17: Infrastructure, cloud and software | B17: 125000 | C17: 118000
A18: Direct delivery cost | B18: 95000 | C18: 92000
A19: Other operating expenses | B19: 105000 | C19: 95000
A20: Total expenses | B20: =SUM(B16:B19) -> 805000 | C20: =SUM(C16:C19) -> 760000
A22: Operating profit / (loss) | B22: =B10-B20 -> -95000 | C22: =C10-C20 -> -102000

Sheet Balance Sheet
A1: Balance Sheet
A2: As at the last day of the month.
A4: Line | B4: Amount
A6: ASSETS
A7: Cash and bank — freely available | B7: 1640000
A8: Cash and bank — restricted (FD, lien-marked, deposits) | B8: 200000
A9: Total cash and bank | B9: =B7+B8 -> 1840000
A10: Trade receivables | B10: 920000
A11: Other current assets | B11: 180000
A12: Fixed assets, net | B12: 340000
A13: Total assets | B13: =B9+B10+B11+B12 -> 3280000
A15: LIABILITIES AND EQUITY
A16: Trade payables | B16: 430000
A17: Statutory dues payable | B17: 145000
A18: Borrowings | B18: 640000
A19: Other current liabilities | B19: 210000
A20: Share capital and reserves | B20: 1855000
A21: Total liabilities and equity | B21: =SUM(B16:B20) -> 3280000
A23: Total assets less total liabilities and equity — must be nil | B23: =B13-B21 -> 0

Sheet Cash Flow
A1: Cash Flow
A2: Actual money in and out of the bank accounts during the month.
A4: Line | B4: Amount
A6: Opening cash and bank, day 1 | B6: 2000000
A8: MONEY IN
A9: Collections from customers | B9: 690000
A10: Other receipts | B10: 20000
A11: Total money in | B11: =SUM(B9:B10) -> 710000
A13: MONEY OUT
A14: Payroll | B14: 470000
A15: Vendors and operating | B15: 250000
A16: Statutory payments | B16: 85000
A17: Other payments | B17: 65000
A18: Total money out | B18: =SUM(B14:B17) -> 870000
A20: Net movement in the month | B20: =B11-B18 -> -160000
A21: Closing cash and bank, last day | B21: =B6+B20 -> 1840000
A23: Memo: gross burn — everything that left the bank | B23: =B18 -> 870000
A24: Memo: net burn — money out less money in | B24: =B18-B11 -> 160000

Sheet Working Capital
A1: Working Capital
A2: Receivables, payables and how well the month collected.
A4: Line | B4: Amount
A6: RECEIVABLES BY AGE
A7: 0 to 30 days | B7: 410000
A8: 31 to 60 days | B8: 260000
A9: 61 to 90 days | B9: 140000
A10: Over 90 days | B10: 110000
A11: Total receivables | B11: =SUM(B7:B10) -> 920000
A13: PAYABLES
A14: Trade payables at month end | B14: 430000
A16: THE MONTH'S BILLING AND COLLECTION
A17: Total billed this month, including GST | B17: 840000
A18: Total collected this month | B18: 690000
A20: Memo: collection efficiency | B20: =IF(B17=0,0,B18/B17) -> 0.82142857
A21: Memo: days to collect | B21: =IF(B17=0,0,B11/B17*30) -> 32.857143

Sheet Customers
A1: Customers
A2: Client count and revenue concentration for the month.
A4: Line | B4: Amount
A6: Paying clients at month end | B6: 14
A7: New clients won this month | B7: 2
A8: Clients lost this month | B8: 1
A10: Revenue from the single largest client | B10: 284000
A11: Revenue from the five largest clients combined | B11: 553800
A13: Memo: largest client as a share of revenue | B13: =IF('Profit and Loss'!B10=0,0,B10/'Profit and Loss'!B10) -> 0.4
A14: Memo: top five as a share of revenue | B14: =IF('Profit and Loss'!B10=0,0,B11/'Profit and Loss'!B10) -> 0.78

Sheet Burn and Runway
A1: Burn and Runway
A2: How fast the cash is going and how long it lasts.
A4: Line | B4: Amount
A6: Cash and bank at month end | B6: ='Balance Sheet'!B9 -> 1840000
A7: Less: restricted balances | B7: ='Balance Sheet'!B8 -> 200000
A8: Cash freely available | B8: =B6-B7 -> 1640000
A10: Net burn this month | B10: ='Cash Flow'!B24 -> 160000
A11: Net burn last month | B11: 165000
A12: Net burn two months ago | B12: 157000
A13: Average net burn, last three months | B13: =AVERAGE(B10:B12) -> 160666.67
A15: Runway in months | B15: =IF(B13<=0,"",B8/B13) -> 10.207469
A17: Alert threshold agreed with the client | B17: 4
A18: Status | B18: =IF(B15="","not calculable",IF(B15<B17,"BELOW THRESHOLD","OK")) -> OK
A20: If this reads BELOW THRESHOLD the portal alerts the founder and PBA on publish.

Sheet Checks
A1: Checks
A2: All five must read PASS before this file is uploaded.
A4: Check | B4: Value A | C4: Value B | D4: Result
A5: Balance sheet balances | B5: ='Balance Sheet'!B13 -> 3280000 | C5: ='Balance Sheet'!B21 -> 3280000 | D5: =IF(ABS(B5-C5)<1,"PASS","FAIL") -> PASS
A6: Receivables ageing ties to the balance sheet | B6: ='Working Capital'!B11 -> 920000 | C6: ='Balance Sheet'!B10 -> 920000 | D6: =IF(ABS(B6-C6)<1,"PASS","FAIL") -> PASS
A7: Closing cash ties to the balance sheet | B7: ='Cash Flow'!B21 -> 1840000 | C7: ='Balance Sheet'!B9 -> 1840000 | D7: =IF(ABS(B7-C7)<1,"PASS","FAIL") -> PASS
A8: Collections agree across sheets | B8: ='Working Capital'!B18 -> 690000 | C8: ='Cash Flow'!B9 -> 690000 | D8: =IF(ABS(B8-C8)<1,"PASS","FAIL") -> PASS
A9: Largest client does not exceed top five, top five does not exceed revenue | B9: =Customers!B10 -> 284000 | C9: =Customers!B11 -> 553800 | D9: =IF(AND(B9<=C9,C9<='Profit and Loss'!B10),"PASS","FAIL") -> PASS
A11: ALL CHECKS | D11: =IF(COUNTIF(D5:D9,"FAIL")=0,"PASS","FAIL") -> PASS
A13: A FAIL does not mean the numbers are wrong — it means two sheets disagree
A14: and one of them needs correcting before the month can be published.

Sheet PBA-DATA
A1: PBA-DATA
A2: Do not edit this sheet. It fills itself and the portal reads it.
A4: Field | B4: Value | C4: Where it comes from
A5: template_version | B5: 1.1 | C5: Fixed. The portal refuses a version it does not know
A6: company_name | B6: ='READ ME'!B28 -> Xploro Private Limited | C6: READ ME sheet
A7: period | B7: ='READ ME'!B29 -> 2026-09 | C7: READ ME sheet
A8: prepared_by | B8: ='READ ME'!B30 -> SPARC & Co, Chartered Accountants | C8: READ ME sheet
A9: prepared_on | B9: ='READ ME'!B31 -> 07/10/2026 | C9: READ ME sheet
A10: checks_all_pass | B10: =Checks!D11 -> PASS | C10: Checks sheet — must be PASS to publish
A12: THE TWENTY-FOUR FIGURES
A13: cash_opening | B13: ='Cash Flow'!B6 -> 2000000 | C13: Cash Flow — opening cash and bank
A14: cash_closing | B14: ='Balance Sheet'!B9 -> 1840000 | C14: Balance Sheet — total cash and bank
A15: cash_restricted | B15: ='Balance Sheet'!B8 -> 200000 | C15: Balance Sheet — restricted balances
A16: gross_burn | B16: ='Cash Flow'!B23 -> 870000 | C16: Cash Flow — total money out
A17: net_burn | B17: ='Cash Flow'!B24 -> 160000 | C17: Cash Flow — money out less money in
A18: expenses_accrual | B18: ='Profit and Loss'!B20 -> 805000 | C18: Profit and Loss — total expenses
A19: revenue_total | B19: ='Profit and Loss'!B10 -> 710000 | C19: Profit and Loss — net revenue
A20: revenue_subscription | B20: ='Profit and Loss'!B7 -> 210000 | C20: Profit and Loss — subscription
A21: revenue_service | B21: ='Profit and Loss'!B8 -> 340000 | C21: Profit and Loss — service
A22: revenue_project | B22: ='Profit and Loss'!B9 -> 160000 | C22: Profit and Loss — project
A23: partner_share_paid | B23: ='Profit and Loss'!B12 -> 180000 | C23: Profit and Loss — paid to partners
A24: clients_active | B24: =Customers!B6 -> 14 | C24: Customers — paying clients at month end
A25: clients_added | B25: =Customers!B7 -> 2 | C25: Customers — won this month
A26: clients_lost | B26: =Customers!B8 -> 1 | C26: Customers — lost this month
A27: top_client_revenue | B27: =Customers!B10 -> 284000 | C27: Customers — largest client
A28: top5_client_revenue | B28: =Customers!B11 -> 553800 | C28: Customers — five largest combined
A29: receivables_total | B29: ='Working Capital'!B11 -> 920000 | C29: Working Capital — total receivables
A30: receivables_0_30 | B30: ='Working Capital'!B7 -> 410000 | C30: Working Capital — 0 to 30 days
A31: receivables_31_60 | B31: ='Working Capital'!B8 -> 260000 | C31: Working Capital — 31 to 60 days
A32: receivables_61_90 | B32: ='Working Capital'!B9 -> 140000 | C32: Working Capital — 61 to 90 days
A33: receivables_90_plus | B33: ='Working Capital'!B10 -> 110000 | C33: Working Capital — over 90 days
A34: payables_total | B34: ='Working Capital'!B14 -> 430000 | C34: Working Capital — trade payables
A35: billed_month | B35: ='Working Capital'!B17 -> 840000 | C35: Working Capital — billed this month
A36: collections_month | B36: ='Working Capital'!B18 -> 690000 | C36: Working Capital — collected this month
A38: THE EXTRA FIGURES (template 1.1)
A39: gst_output | B39: ='Tax and People'!B5 -> 127800
A40: gst_itc | B40: ='Tax and People'!B6 -> 41000
A41: gst_paid_cash | B41: ='Tax and People'!B7 -> 86800
A42: igst | B42: ='Tax and People'!B8 -> 76680
A43: cgst | B43: ='Tax and People'!B9 -> 25560
...

Sheet Tax and People
A1: Tax and People
A2: Fill the amber cells for the month, in rupees. These feed the taxes, team and expense sections of the dashboard.
A4: Figure | B4: Value | C4: Where it comes from
A5: GST charged on sales (output tax) | B5: 127800 | C5: From the GST working: total output tax for the month, all GSTINs.
A6: GST credit used (input tax credit) | B6: 41000 | C6: Credit set off against the output tax in GSTR-3B.
A7: GST paid in cash | B7: 86800 | C7: Output tax less credit: the GSTR-3B challan amount.
A8: IGST (output) | B8: 76680 | C8: Output tax on sales to other states.
A9: CGST (output) | B9: 25560 | C9: Output tax on sales within the state, central half.
A10: SGST (output) | B10: 25560 | C10: Output tax on sales within the state, state half.
A11: TDS deposited — salaries | B11: 31000 | C11: Section 192, from the TDS challan.
A12: TDS deposited — vendors and professionals | B12: 12400 | C12: Sections 194C, 194J and similar.
A13: TDS deposited — rent | B13: 4000 | C13: Section 194-I.
A14: Professional tax paid | B14: 0 | C14: From the professional tax challan. 0 if none was due this month.
A15: Interest and late fees paid | B15: 0 | C15: Anything paid only because a filing or payment was late. 0 if none.
A16: Employees on payroll at month end | B16: 14 | C16: From the payroll register.
... A19: Expenses — salaries | B19: 450000 | C19: From the P&L. The eight heads must add up to total expenses.
A20: Expenses — contractors | B20: 90000
A21: Expenses — cloud and AI tools | B21: 72000
A22: Expenses — marketing | B22: 48000
A23: Expenses — office rent | B23: 40000
A24: Expenses — travel | B24: 32000
A25: Expenses — software | B25: 24000
A26: Expenses — everything else | B26: 49000
A27: Reason for interest or late fees | C27: One line. Required if interest or late fees above are more than 0.
A28: Expense heads total (must equal total expenses) | B28: =SUM(B19:B26) -> 805000
